Workbook

Sheet Dashboard
B2: 📈 Summary Dashboard
B4: KEY PERFORMANCE INDICATORS
B5: Total Employees | D5: Avg Base Salary (NPR) | F5: Total Comp Paid (NPR) | H5: Avg Performance | J5: Avg Attendance | L5: Total Projects Done
B7: ='Employee Database'!A503 -> TOTALS / AVERAGES | D7: ='Employee Database'!I503 -> 140280 | F7: ='Employee Database'!L503 -> 82839263 | H7: ='Employee Database'!N503 -> 3.69766 | J7: ='Employee Database'!O503 -> 0.860214 | L7: ='Employee Database'!P503 -> 10301
B11: Total Sales (NPR) | D11: Total Net Revenue (NPR) | F11: Gross Profit (NPR) | H11: Total Units Sold | J11: Total Returns | L11: COGS Total (NPR)
B13: ='Monthly Sales'!J303 -> 712485479 | D13: ='Monthly Sales'!O303 -> 6.5966148e+08 | F13: ='Monthly Sales'!L303 -> 3.0434895e+08 | H13: ='Monthly Sales'!H303 -> 72621 | J13: ='Monthly Sales'!P303 -> 1833 | L13: ='Monthly Sales'!K303 -> 4.0813653e+08
B17: Total Students | D17: Avg Percentage | F17: Avg GPA | H17: Avg Attendance | J17: Total Stock Value | L17: Total Assets
B19: =COUNTA('Student Records'!A3:A402) -> 400 | D19: ='Student Records'!M403 -> 59.615 | F19: ='Student Records'!O403 -> 2.143 | H19: ='Student Records'!P403 -> 0.7638225 | J19: =Inventory!J253 -> 3606432600 | L19: =Inventory!T253 -> 3827058500
B23: DEPARTMENT HEADCOUNT (from Employee DB)
B24: Department | C24: Headcount | D24: Avg Salary (NPR) | E24: Total Comp (NPR) | F24: Avg Performance
B25: Engineering | C25: =COUNTIF('Employee Database'!C3:C502,"Engineering") -> 33 | D25: =AVERAGEIF('Employee Database'!C3:C502,B25,'Employee Database'!I3:I502) -> 133121.21 | E25: =SUMIF('Employee Database'!C3:C502,B25,'Employee Database'!L3:L502) -> 5170392 | F25: =AVERAGEIF('Employee Database'!C3:C502,B25,'Employee Database'!N3:N502) -> 3.630303
B26: Sales | C26: =COUNTIF('Employee Database'!C3:C502,"Sales") -> 52 | D26: =AVERAGEIF('Employee Database'!C3:C502,B26,'Employee Database'!I3:I502) -> 124423.08 | E26: =SUMIF('Employee Database'!C3:C502,B26,'Employee Database'!L3:L502) -> 7601981 | F26: =AVERAGEIF('Employee Database'!C3:C502,B26,'Employee Database'!N3:N502) -> 3.6907692
B27: Marketing | C27: =COUNTIF('Employee Database'!C3:C502,"Marketing") -> 53 | D27: =AVERAGEIF('Employee Database'!C3:C502,B27,'Employee Database'!I3:I502) -> 146245.28 | E27: =SUMIF('Employee Database'!C3:C502,B27,'Employee Database'!L3:L502) -> 9055469 | F27: =AVERAGEIF('Employee Database'!C3:C502,B27,'Employee Database'!N3:N502) -> 3.68
B28: HR | C28: =COUNTIF('Employee Database'!C3:C502,"HR") -> 48 | D28: =AVERAGEIF('Employee Database'!C3:C502,B28,'Employee Database'!I3:I502) -> 152083.33 | E28: =SUMIF('Employee Database'!C3:C502,B28,'Employee Database'!L3:L502) -> 8555174 | F28: =AVERAGEIF('Employee Database'!C3:C502,B28,'Employee Database'!N3:N502) -> 3.7635417
B29: Finance | C29: =COUNTIF('Employee Database'!C3:C502,"Finance") -> 53 | D29: =AVERAGEIF('Employee Database'!C3:C502,B29,'Employee Database'!I3:I502) -> 158641.51 | E29: =SUMIF('Employee Database'!C3:C502,B29,'Employee Database'!L3:L502) -> 9920981 | F29: =AVERAGEIF('Employee Database'!C3:C502,B29,'Employee Database'!N3:N502) -> 3.7984906
B30: Operations | C30: =COUNTIF('Employee Database'!C3:C502,"Operations") -> 52 | D30: =AVERAGEIF('Employee Database'!C3:C502,B30,'Employee Database'!I3:I502) -> 135192.31 | E30: =SUMIF('Employee Database'!C3:C502,B30,'Employee Database'!L3:L502) -> 8318940 | F30: =AVERAGEIF('Employee Database'!C3:C502,B30,'Employee Database'!N3:N502) -> 3.5315385
B31: Legal | C31: =COUNTIF('Employee Database'!C3:C502,"Legal") -> 57 | D31: =AVERAGEIF('Employee Database'!C3:C502,B31,'Employee Database'!I3:I502) -> 136245.61 | E31: =SUMIF('Employee Database'!C3:C502,B31,'Employee Database'!L3:L502) -> 9178731 | F31: =AVERAGEIF('Employee Database'!C3:C502,B31,'Employee Database'!N3:N502) -> 3.6177193
B32: Product | C32: =COUNTIF('Employee Database'!C3:C502,"Product") -> 57 | D32: =AVERAGEIF('Employee Database'!C3:C502,B32,'Employee Database'!I3:I502) -> 144894.74 | E32: =SUMIF('Employee Database'!C3:C502,B32,'Employee Database'!L3:L502) -> 9903822 | F32: =AVERAGEIF('Employee Database'!C3:C502,B32,'Employee Database'!N3:N502) -> 3.7624561
B33: Design | C33: =COUNTIF('Employee Database'!C3:C502,"Design") -> 43 | D33: =AVERAGEIF('Employee Database'!C3:C502,B33,'Employee Database'!I3:I502) -> 140860.47 | E33: =SUMIF('Employee Database'!C3:C502,B33,'Employee Database'!L3:L502) -> 7213240 | F33: =AVERAGEIF('Employee Database'!C3:C502,B33,'Employee Database'!N3:N502) -> 3.7704651
B34: Support | C34: =COUNTIF('Employee Database'!C3:C502,"Support") -> 52 | D34: =AVERAGEIF('Employee Database'!C3:C502,B34,'Employee Database'!I3:I502) -> 128961.54 | E34: =SUMIF('Employee Database'!C3:C502,B34,'Employee Database'!L3:L502) -> 7920533 | F34: =AVERAGEIF('Employee Database'!C3:C502,B34,'Employee Database'!N3:N502) -> 3.7242308

Sheet Employee Database
A1: 🏢 Employee Database — FY 2024–25
A2: Emp ID | B2: Full Name | C2: Department | D2: Job Grade | E2: Location | F2: Gender | G2: Date of Birth | H2: Join Date | I2: Base Salary (NPR) | J2: Bonus % | K2: Annual Bonus (NPR) | L2: Total Comp (NPR) | M2: Experience (Yrs) | N2: Performance Score | O2: Attendance % | P2: Projects Done | Q2: Training Hours | R2: Email | S2: Phone | T2: Status
A3: EMP0001 | B3: Daniel Doyle | C3: Sales | D3: Junior | E3: Butwal | F3: Male | G3: 33261 | H3: 38531 | I3: 83000 | J3: 0.085 | K3: =J3*I3 -> 7055 | L3: =I3+K3 -> 90055 | M3: 19.5 | N3: 2.76 | O3: 0.922 | P3: 35 | Q3: 32 | R3: garzaanthony@example.org | S3: 538.990.8386 | T3: On Leave
A4: EMP0002 | B4: Robert Wolfe | C4: Legal | D4: Junior | E4: Kathmandu | F4: Male | G4: 32583 | H4: 44116 | I4: 82000 | J4: 0.108 | K4: =J4*I4 -> 8856 | L4: =I4+K4 -> 90856 | M4: 4.2 | N4: 4.01 | O4: 0.868 | P4: 35 | Q4: 117 | R4: joshua35@example.org | S4: 361-855-9407 | T4: Active
A5: EMP0003 | B5: Stacey Ward | C5: Product | D5: Manager | E5: Butwal | F5: Male | G5: 25684 | H5: 40440 | I5: 223000 | J5: 0.251 | K5: =J5*I5 -> 55973 | L5: =I5+K5 -> 278973 | M5: 14.3 | N5: 4.25 | O5: 0.802 | P5: 10 | Q5: 65 | R5: janetwilliams@example.org | S5: 001-341-431-64 | T5: Active
A6: EMP0004 | B6: Devin Schaefer | C6: Sales | D6: Junior | E6: Hetauda | F6: Male | G6: 31838 | H6: 40096 | I6: 119000 | J6: 0.262 | K6: =J6*I6 -> 31178 | L6: =I6+K6 -> 150178 | M6: 15.2 | N6: 4.01 | O6: 0.942 | P6: 30 | Q6: 147 | R6: gabriellecameron@example.org | S6: 505.964.1395 | T6: Active
A7: EMP0005 | B7: Derek Wright | C7: Legal | D7: Junior | E7: Butwal | F7: Other | G7: 29966 | H7: 44864 | I7: 187000 | J7: 0.271 | K7: =J7*I7 -> 50677 | L7: =I7+K7 -> 237677 | M7: 2.2 | N7: 3.4 | O7: 0.758 | P7: 5 | Q7: 21 | R7: julie69@example.com | S7: (332)887-1012x | T7: Resigned
A8: EMP0006 | B8: Tricia Valencia | C8: HR | D8: VP | E8: Butwal | F8: Male | G8: 29777 | H8: 45445 | I8: 249000 | J8: 0.108 | K8: =J8*I8 -> 26892 | L8: =I8+K8 -> 275892 | M8: 0.6 | N8: 2.75 | O8: 0.783 | P8: 24 | Q8: 51 | R8: frazierdanny@example.net | S8: 001-645-514-62 | T8: Active
A9: EMP0007 | B9: Paula Moreno | C9: Operations | D9: Mid | E9: Butwal | F9: Other | G9: 26685 | H9: 43782 | I9: 204000 | J9: 0.212 | K9: =J9*I9 -> 43248 | L9: =I9+K9 -> 247248 | M9: 5.1 | N9: 4.02 | O9: 0.751 | P9: 16 | Q9: 51 | R9: georgetracy@example.org | S9: (443)903-9117x | T9: Active
A10: EMP0008 | B10: Lisa Brandt | C10: Legal | D10: Senior | E10: Biratnagar | F10: Other | G10: 37416 | H10: 39528 | I10: 110000 | J10: 0.261 | K10: =J10*I10 -> 28710 | L10: =I10+K10 -> 138710 | M10: 16.8 | N10: 4.44 | O10: 0.769 | P10: 3 | Q10: 90 | R10: jenniferross@example.net | S10: +1-557-587-133 | T10: Active
A11: EMP0009 | B11: Austin Johnson | C11: Finance | D11: Junior | E11: Biratnagar | F11: Other | G11: 24717 | H11: 43392 | I11: 213000 | J11: 0.129 | K11: =J11*I11 -> 27477 | L11: =I11+K11 -> 240477 | M11: 6.2 | N11: 4.14 | O11: 0.819 | P11: 30 | Q11: 46 | R11: chad34@example.net | S11: 838.729.9737x6 | T11: Active
A12: EMP0010 | B12: Megan Joyce | C12: Marketing | D12: Mid | E12: Butwal | F12: Other | G12: 30344 | H12: 41678 | I12: 178000 | J12: 0.157 | K12: =J12*I12 -> 27946 | L12: =I12+K12 -> 205946 | M12: 10.9 | N12: 3.96 | O12: 0.809 | P12: 9 | Q12: 140 | R12: brownjessica@example.org | S12: 933.587.2624 | T12: Active
A13: EMP0011 | B13: Savannah Garcia | C13: Sales | D13: VP | E13: Kathmandu | F13: Male | G13: 36438 | H13: 38889 | I13: 65000 | J13: 0.207 | K13: =J13*I13 -> 13455 | L13: =I13+K13 -> 78455 | M13: 18.5 | N13: 4.48 | O13: 0.827 | P13: 5 | Q13: 108 | R13: novaksara@example.org | S13: (267)873-6026 | T13: Active
A14: EMP0012 | B14: Jay Bernard | C14: Support | D14: Lead | E14: Butwal | F14: Other | G14: 28204 | H14: 43935 | I14: 28000 | J14: 0.22 | K14: =J14*I14 -> 6160 | L14: =I14+K14 -> 34160 | M14: 4.7 | N14: 2.79 | O14: 0.965 | P14: 18 | Q14: 174 | R14: smoore@example.org | S14: 4982050097 | T14: Active
... A502: EMP0500 | B502: Brandy Jacobson | C502: HR | D502: Lead | E502: Hetauda | F502: Female | G502: 31597 | H502: 42354 | I502: 90000 | J502: 0.091 | K502: =J502*I502 -> 8190 | L502: =I502+K502 -> 98190 | M502: 9 | N502: 4.34 | O502: 0.817 | P502: 25 | Q502: 66 | R502: kevincollins@example.org | S502: 393.911.0291x8 | T502: Active
A503: TOTALS / AVERAGES | I503: =AVERAGE(I3:I502) -> 140280 | K503: =SUM(K3:K502) -> 12699263 | L503: =SUM(L3:L502) -> 82839263 | M503: =AVERAGE(M3:M502) -> 10.5136 | N503: =AVERAGE(N3:N502) -> 3.69766 | O503: =AVERAGE(O3:O502) -> 0.860214 | P503: =SUM(P3:P502) -> 10301 | Q503: =SUM(Q3:Q502) -> 52772

Sheet Monthly Sales
A1: 📊 Monthly Sales Report — 2022 to 2024
A2: Sale ID | B2: Month | C2: Year | D2: Product | E2: Category | F2: Region | G2: Channel | H2: Units Sold | I2: Unit Price (NPR) | J2: Revenue (NPR) | K2: COGS (NPR) | L2: Gross Profit (NPR) | M2: Gross Margin % | N2: Discount % | O2: Net Revenue (NPR) | P2: Returns | Q2: Return Rate % | R2: Rep Name | S2: Quarter | T2: Target Met?
A3: SL00001 | B3: Feb | C3: 2023 | D3: Drawing Tablet | E3: Input | F3: Gandaki | G3: Government | H3: 392 | I3: 2999 | J3: =H3*I3 -> 1175608 | K3: =J3*0.68 -> 799413.44 | L3: =J3-K3 -> 376194.56 | M3: =IF(J3=0,0,L3/J3) -> 0.32 | N3: 0.12 | O3: =J3*(1-N3) -> 1034535 | P3: 8 | Q3: =IF(H3=0,0,P3/H3) -> 0.020408163 | R3: Jonathan Myers | S3: Q1 | T3: Yes
A4: SL00002 | B4: Nov | C4: 2024 | D4: Cooling Pad | E4: Accessories | F4: Karnali | G4: Wholesale | H4: 212 | I4: 2499 | J4: =H4*I4 -> 529788 | K4: =J4*0.66 -> 349660.08 | L4: =J4-K4 -> 180127.92 | M4: =IF(J4=0,0,L4/J4) -> 0.34 | N4: 0.03 | O4: =J4*(1-N4) -> 513894.36 | P4: 4 | Q4: =IF(H4=0,0,P4/H4) -> 0.018867925 | R4: Elizabeth Webb | S4: Q4 | T4: Yes
A5: SL00003 | B5: Nov | C5: 2023 | D5: Smart Headset | E5: Audio | F5: Lumbini | G5: Wholesale | H5: 359 | I5: 11999 | J5: =H5*I5 -> 4307641 | K5: =J5*0.57 -> 2455355.4 | L5: =J5-K5 -> 1852285.6 | M5: =IF(J5=0,0,L5/J5) -> 0.43 | N5: 0.05 | O5: =J5*(1-N5) -> 4092259 | P5: 4 | Q5: =IF(H5=0,0,P5/H5) -> 0.011142061 | R5: David Abbott | S5: Q4 | T5: Yes
A6: SL00004 | B6: Sep | C6: 2022 | D6: USB-C Hub | E6: Accessories | F6: Bagmati | G6: Wholesale | H6: 138 | I6: 12999 | J6: =H6*I6 -> 1793862 | K6: =J6*0.63 -> 1130133.1 | L6: =J6-K6 -> 663728.94 | M6: =IF(J6=0,0,L6/J6) -> 0.37 | N6: 0.11 | O6: =J6*(1-N6) -> 1596537.2 | P6: 1 | Q6: =IF(H6=0,0,P6/H6) -> 0.0072463768 | R6: Lonnie Gonzales | S6: Q3 | T6: Yes
A7: SL00005 | B7: Mar | C7: 2022 | D7: RAM 16GB | E7: Memory | F7: Gandaki | G7: Wholesale | H7: 216 | I7: 35999 | J7: =H7*I7 -> 7775784 | K7: =J7*0.65 -> 5054259.6 | L7: =J7-K7 -> 2721524.4 | M7: =IF(J7=0,0,L7/J7) -> 0.35 | N7: 0.07 | O7: =J7*(1-N7) -> 7231479.1 | P7: 5 | Q7: =IF(H7=0,0,P7/H7) -> 0.023148148 | R7: Barbara Thomas | S7: Q1 | T7: No
A8: SL00006 | B8: Dec | C8: 2022 | D8: Webcam HD | E8: Peripherals | F8: Bagmati | G8: Retail Store | H8: 29 | I8: 35999 | J8: =H8*I8 -> 1043971 | K8: =J8*0.64 -> 668141.44 | L8: =J8-K8 -> 375829.56 | M8: =IF(J8=0,0,L8/J8) -> 0.36 | N8: 0.01 | O8: =J8*(1-N8) -> 1033531.3 | P8: 1 | Q8: =IF(H8=0,0,P8/H8) -> 0.034482759 | R8: Charles Garner | S8: Q4 | T8: Yes
A9: SL00007 | B9: Apr | C9: 2023 | D9: Cable Organiser | E9: Accessories | F9: Lumbini | G9: Online | H9: 63 | I9: 2999 | J9: =H9*I9 -> 188937 | K9: =J9*0.63 -> 119030.31 | L9: =J9-K9 -> 69906.69 | M9: =IF(J9=0,0,L9/J9) -> 0.37 | N9: 0.06 | O9: =J9*(1-N9) -> 177600.78 | P9: 3 | Q9: =IF(H9=0,0,P9/H9) -> 0.047619048 | R9: Jorge Lyons | S9: Q2 | T9: Yes
A10: SL00008 | B10: Dec | C10: 2022 | D10: Mechanical Keyboard | E10: Peripherals | F10: Lumbini | G10: Online | H10: 267 | I10: 24999 | J10: =H10*I10 -> 6674733 | K10: =J10*0.7 -> 4672313.1 | L10: =J10-K10 -> 2002419.9 | M10: =IF(J10=0,0,L10/J10) -> 0.3 | N10: 0.07 | O10: =J10*(1-N10) -> 6207501.7 | P10: 10 | Q10: =IF(H10=0,0,P10/H10) -> 0.037453184 | R10: John Roberts | S10: Q4 | T10: Yes
A11: SL00009 | B11: Jun | C11: 2022 | D11: Drawing Tablet | E11: Input | F11: Sudurpashchim | G11: Online | H11: 382 | I11: 299 | J11: =H11*I11 -> 114218 | K11: =J11*0.59 -> 67388.62 | L11: =J11-K11 -> 46829.38 | M11: =IF(J11=0,0,L11/J11) -> 0.41 | N11: 0.02 | O11: =J11*(1-N11) -> 111933.64 | P11: 15 | Q11: =IF(H11=0,0,P11/H11) -> 0.039267016 | R11: Kevin Richardson | S11: Q2 | T11: Yes
A12: SL00010 | B12: Apr | C12: 2023 | D12: Screen Cleaner | E12: Accessories | F12: Bagmati | G12: Retail Store | H12: 499 | I12: 7999 | J12: =H12*I12 -> 3991501 | K12: =J12*0.51 -> 2035665.5 | L12: =J12-K12 -> 1955835.5 | M12: =IF(J12=0,0,L12/J12) -> 0.49 | N12: 0.07 | O12: =J12*(1-N12) -> 3712095.9 | P12: 0 | Q12: =IF(H12=0,0,P12/H12) -> 0 | R12: James Marsh | S12: Q2 | T12: Yes
A13: SL00011 | B13: May | C13: 2024 | D13: Wireless Mouse | E13: Peripherals | F13: Lumbini | G13: Retail Store | H13: 5 | I13: 4999 | J13: =H13*I13 -> 24995 | K13: =J13*0.6 -> 14997 | L13: =J13-K13 -> 9998 | M13: =IF(J13=0,0,L13/J13) -> 0.4 | N13: 0.1 | O13: =J13*(1-N13) -> 22495.5 | P13: 0 | Q13: =IF(H13=0,0,P13/H13) -> 0 | R13: Robert Hernandez | S13: Q2 | T13: Yes
A14: SL00012 | B14: Feb | C14: 2022 | D14: USB-C Hub | E14: Accessories | F14: Lumbini | G14: Online | H14: 352 | I14: 11999 | J14: =H14*I14 -> 4223648 | K14: =J14*0.53 -> 2238533.4 | L14: =J14-K14 -> 1985114.6 | M14: =IF(J14=0,0,L14/J14) -> 0.47 | N14: 0.15 | O14: =J14*(1-N14) -> 3590100.8 | P14: 1 | Q14: =IF(H14=0,0,P14/H14) -> 0.0028409091 | R14: Bryan Price | S14: Q1 | T14: Yes
A15: SL00013 | B15: Jun | C15: 2024 | D15: USB-C Hub | E15: Accessories | F15: Sudurpashchim | G15: Government | H15: 406 | I15: 7999 | J15: =H15*I15 -> 3247594 | K15: =J15*0.48 -> 1558845.1 | L15: =J15-K15 -> 1688748.9 | M15: =IF(J15=0,0,L15/J15) -> 0.52 | N15: 0.03 | O15: =J15*(1-N15) -> 3150166.2 | P15: 17 | Q15: =IF(H15=0,0,P15/H15) -> 0.041871921 | R15: Amanda Santos | S15: Q2 | T15: Yes
A16: SL00014 | B16: Aug | C16: 2024 | D16: Mechanical Keyboard | E16: Peripherals | F16: Bagmati | G16: Corporate | H16: 184 | I16: 3999 | J16: =H16*I16 -> 735816 | K16: =J16*0.48 -> 353191.68 | L16: =J16-K16 -> 382624.32 | M16: =IF(J16=0,0,L16/J16) -> 0.52 | N16: 0.13 | O16: =J16*(1-N16) -> 640159.92 | P16: 7 | Q16: =IF(H16=0,0,P16/H16) -> 0.038043478 | R16: Jill Odonnell | S16: Q3 | T16: No
A17: SL00015 | B17: Sep | C17: 2023 | D17: Cooling Pad | E17: Accessories | F17: Sudurpashchim | G17: Corporate | H17: 98 | I17: 11999 | J17: =H17*I17 -> 1175902 | K17: =J17*0.5 -> 587951 | L17: =J17-K17 -> 587951 | M17: =IF(J17=0,0,L17/J17) -> 0.5 | N17: 0.05 | O17: =J17*(1-N17) -> 1117106.9 | P17: 3 | Q17: =IF(H17=0,0,P17/H17) -> 0.030612245 | R17: Charles Khan | S17: Q3 | T17: Yes
A18: SL00016 | B18: Oct | C18: 2024 | D18: USB-C Hub | E18: Accessories | F18: Bagmati | G18: Government | H18: 80 | I18: 9999 | J18: =H18*I18 -> 799920 | K18: =J18*0.52 -> 415958.4 | L18: =J18-K18 -> 383961.6 | M18: =IF(J18=0,0,L18/J18) -> 0.48 | N18: 0.04 | O18: =J18*(1-N18) -> 767923.2 | P18: 2 | Q18: =IF(H18=0,0,P18/H18) -> 0.025 | R18: Adam Moore | S18: Q4 | T18: No
A19: SL00017 | B19: Jan | C19: 2024 | D19: Cooling Pad | E19: Accessories | F19: Lumbini | G19: Retail Store | H19: 453 | I19: 4999 | J19: =H19*I19 -> 2264547 | K19: =J19*0.6 -> 1358728.2 | L19: =J19-K19 -> 905818.8 | M19: =IF(J19=0,0,L19/J19) -> 0.4 | N19: 0.05 | O19: =J19*(1-N19) -> 2151319.6 | P19: 19 | Q19: =IF(H19=0,0,P19/H19) -> 0.041942605 | R19: Shannon Clark | S19: Q1 | T19: Yes
A20: SL00018 | B20: Jun | C20: 2024 | D20: Wireless Mouse | E20: Peripherals | F20: Sudurpashchim | G20: Government | H20: 420 | I20: 15999 | J20: =H20*I20 -> 6719580 | K20: =J20*0.5 -> 3359790 | L20: =J20-K20 -> 3359790 | M20: =IF(J20=0,0,L20/J20) -> 0.5 | N20: 0.1 | O20: =J20*(1-N20) -> 6047622 | P20: 17 | Q20: =IF(H20=0,0,P20/H20) -> 0.04047619 | R20: Kelly Palmer | S20: Q2 | T20: Yes
A21: SL00019 | B21: Oct | C21: 2023 | D21: Webcam HD | E21: Peripherals | F21: Lumbini | G21: Wholesale | H21: 57 | I21: 7999 | J21: =H21*I21 -> 455943 | K21: =J21*0.58 -> 264446.94 | L21: =J21-K21 -> 191496.06 | M21: =IF(J21=0,0,L21/J21) -> 0.42 | N21: 0.01 | O21: =J21*(1-N21) -> 451383.57 | P21: 0 | Q21: =IF(H21=0,0,P21/H21) -> 0 | R21: Christian Rios | S21: Q4 | T21: Yes
A22: SL00020 | B22: Jan | C22: 2022 | D22: Wireless Mouse | E22: Peripherals | F22: Lumbini | G22: Retail Store | H22: 51 | I22: 4999 | J22: =H22*I22 -> 254949 | K22: =J22*0.59 -> 150419.91 | L22: =J22-K22 -> 104529.09 | M22: =IF(J22=0,0,L22/J22) -> 0.41 | N22: 0.13 | O22: =J22*(1-N22) -> 221805.63 | P22: 2 | Q22: =IF(H22=0,0,P22/H22) -> 0.039215686 | R22: Julia Trevino | S22: Q1 | T22: No
A23: SL00021 | B23: Sep | C23: 2024 | D23: Portable Charger | E23: Accessories | F23: Madhesh | G23: Wholesale | H23: 26 | I23: 8999 | J23: =H23*I23 -> 233974 | K23: =J23*0.51 -> 119326.74 | L23: =J23-K23 -> 114647.26 | M23: =IF(J23=0,0,L23/J23) -> 0.49 | N23: 0.11 | O23: =J23*(1-N23) -> 208236.86 | P23: 0 | Q23: =IF(H23=0,0,P23/H23) -> 0 | R23: Richard Barrett | S23: Q3 | T23: Yes
A24: SL00022 | B24: Nov | C24: 2023 | D24: Screen Cleaner | E24: Accessories | F24: Karnali | G24: Online | H24: 240 | I24: 2999 | J24: =H24*I24 -> 719760 | K24: =J24*0.61 -> 439053.6 | L24: =J24-K24 -> 280706.4 | M24: =IF(J24=0,0,L24/J24) -> 0.39 | N24: 0.05 | O24: =J24*(1-N24) -> 683772 | P24: 11 | Q24: =IF(H24=0,0,P24/H24) -> 0.045833333 | R24: Andrea Franco | S24: Q4 | T24: No
A25: SL00023 | B25: Jun | C25: 2024 | D25: Laptop Pro X | E25: Computing | F25: Karnali | G25: Government | H25: 137 | I25: 1999 | J25: =H25*I25 -> 273863 | K25: =J25*0.46 -> 125976.98 | L25: =J25-K25 -> 147886.02 | M25: =IF(J25=0,0,L25/J25) -> 0.54 | N25: 0.01 | O25: =J25*(1-N25) -> 271124.37 | P25: 2 | Q25: =IF(H25=0,0,P25/H25) -> 0.01459854 | R25: Dr. Larry White | S25: Q2 | T25: Yes
A26: SL00024 | B26: Apr | C26: 2024 | D26: Wireless Mouse | E26: Peripherals | F26: Bagmati | G26: Retail Store | H26: 273 | I26: 15999 | J26: =H26*I26 -> 4367727 | K26: =J26*0.5 -> 2183863.5 | L26: =J26-K26 -> 2183863.5 | M26: =IF(J26=0,0,L26/J26) -> 0.5 | N26: 0.08 | O26: =J26*(1-N26) -> 4018308.8 | P26: 3 | Q26: =IF(H26=0,0,P26/H26) -> 0.010989011 | R26: Katie Hopkins | S26: Q2 | T26: Yes
A27: SL00025 | B27: Sep | C27: 2024 | D27: Cooling Pad | E27: Accessories | F27: Lumbini | G27: Online | H27: 393 | I27: 24999 | J27: =H27*I27 -> 9824607 | K27: =J27*0.59 -> 5796518.1 | L27: =J27-K27 -> 4028088.9 | M27: =IF(J27=0,0,L27/J27) -> 0.41 | N27: 0.1 | O27: =J27*(1-N27) -> 8842146.3 | P27: 13 | Q27: =IF(H27=0,0,P27/H27) -> 0.03307888 | R27: Michael Chapman | S27: Q3 | T27: Yes
A28: SL00026 | B28: Mar | C28: 2022 | D28: Cooling Pad | E28: Accessories | F28: Lumbini | G28: Government | H28: 173 | I28: 24999 | J28: =H28*I28 -> 4324827 | K28: =J28*0.49 -> 2119165.2 | L28: =J28-K28 -> 2205661.8 | M28: =IF(J28=0,0,L28/J28) -> 0.51 | N28: 0.15 | O28: =J28*(1-N28) -> 3676103 | P28: 7 | Q28: =IF(H28=0,0,P28/H28) -> 0.040462428 | R28: Lauren Gallegos | S28: Q1 | T28: Yes
A29: SL00027 | B29: Jun | C29: 2024 | D29: Webcam HD | E29: Peripherals | F29: Karnali | G29: Wholesale | H29: 212 | I29: 2999 | J29: =H29*I29 -> 635788 | K29: =J29*0.61 -> 387830.68 | L29: =J29-K29 -> 247957.32 | M29: =IF(J29=0,0,L29/J29) -> 0.39 | N29: 0.12 | O29: =J29*(1-N29) -> 559493.44 | P29: 5 | Q29: =IF(H29=0,0,P29/H29) -> 0.023584906 | R29: Allen Quinn | S29: Q2 | T29: Yes
A30: SL00028 | B30: Oct | C30: 2024 | D30: Mechanical Keyboard | E30: Peripherals | F30: Lumbini | G30: Government | H30: 475 | I30: 3999 | J30: =H30*I30 -> 1899525 | K30: =J30*0.51 -> 968757.75 | L30: =J30-K30 -> 930767.25 | M30: =IF(J30=0,0,L30/J30) -> 0.49 | N30: 0.14 | O30: =J30*(1-N30) -> 1633591.5 | P30: 14 | Q30: =IF(H30=0,0,P30/H30) -> 0.029473684 | R30: Maurice Porter | S30: Q4 | T30: No
A31: SL00029 | B31: Jan | C31: 2024 | D31: Laptop Pro X | E31: Computing | F31: Koshi | G31: Government | H31: 9 | I31: 1999 | J31: =H31*I31 -> 17991 | K31: =J31*0.48 -> 8635.68 | L31: =J31-K31 -> 9355.32 | M31: =IF(J31=0,0,L31/J31) -> 0.52 | N31: 0.13 | O31: =J31*(1-N31) -> 15652.17 | P31: 0 | Q31: =IF(H31=0,0,P31/H31) -> 0 | R31: Erica Hall | S31: Q1 | T31: Yes
A32: SL00030 | B32: Apr | C32: 2022 | D32: Cable Organiser | E32: Accessories | F32: Koshi | G32: Online | H32: 396 | I32: 799 | J32: =H32*I32 -> 316404 | K32: =J32*0.69 -> 218318.76 | L32: =J32-K32 -> 98085.24 | M32: =IF(J32=0,0,L32/J32) -> 0.31 | N32: 0.12 | O32: =J32*(1-N32) -> 278435.52 | P32: 17 | Q32: =IF(H32=0,0,P32/H32) -> 0.042929293 | R32: Sylvia Flynn | S32: Q2 | T32: Yes
A33: SL00031 | B33: Feb | C33: 2022 | D33: RAM 16GB | E33: Memory | F33: Koshi | G33: Retail Store | H33: 71 | I33: 35999 | J33: =H33*I33 -> 2555929 | K33: =J33*0.54 -> 1380201.7 | L33: =J33-K33 -> 1175727.3 | M33: =IF(J33=0,0,L33/J33) -> 0.46 | N33: 0.09 | O33: =J33*(1-N33) -> 2325895.4 | P33: 1 | Q33: =IF(H33=0,0,P33/H33) -> 0.014084507 | R33: Spencer Chandler | S33: Q1 | T33: Yes
A34: SL00032 | B34: May | C34: 2022 | D34: Smart Headset | E34: Audio | F34: Lumbini | G34: Government | H34: 470 | I34: 2499 | J34: =H34*I34 -> 1174530 | K34: =J34*0.63 -> 739953.9 | L34: =J34-K34 -> 434576.1 | M34: =IF(J34=0,0,L34/J34) -> 0.37 | N34: 0.11 | O34: =J34*(1-N34) -> 1045331.7 | P34: 15 | Q34: =IF(H34=0,0,P34/H34) -> 0.031914894 | R34: William Nielsen | S34: Q2 | T34: Yes
A35: SL00033 | B35: Aug | C35: 2024 | D35: Portable Charger | E35: Accessories | F35: Madhesh | G35: Online | H35: 305 | I35: 24999 | J35: =H35*I35 -> 7624695 | K35: =J35*0.53 -> 4041088.4 | L35: =J35-K35 -> 3583606.6 | M35: =IF(J35=0,0,L35/J35) -> 0.47 | N35: 0.11 | O35: =J35*(1-N35) -> 6785978.5 | P35: 12 | Q35: =IF(H35=0,0,P35/H35) -> 0.039344262 | R35: David Johnson | S35: Q3 | T35: Yes
A36: SL00034 | B36: Jan | C36: 2023 | D36: Webcam HD | E36: Peripherals | F36: Karnali | G36: Corporate | H36: 214 | I36: 299 | J36: =H36*I36 -> 63986 | K36: =J36*0.67 -> 42870.62 | L36: =J36-K36 -> 21115.38 | M36: =IF(J36=0,0,L36/J36) -> 0.33 | N36: 0.13 | O36: =J36*(1-N36) -> 55667.82 | P36: 3 | Q36: =IF(H36=0,0,P36/H36) -> 0.014018692 | R36: Jessica Brooks | S36: Q1 | T36: Yes
A37: SL00035 | B37: Nov | C37: 2024 | D37: SSD 1TB | E37: Storage | F37: Bagmati | G37: Wholesale | H37: 269 | I37: 4999 | J37: =H37*I37 -> 1344731 | K37: =J37*0.53 -> 712707.43 | L37: =J37-K37 -> 632023.57 | M37: =IF(J37=0,0,L37/J37) -> 0.47 | N37: 0.08 | O37: =J37*(1-N37) -> 1237152.5 | P37: 5 | Q37: =IF(H37=0,0,P37/H37) -> 0.018587361 | R37: Alyssa Thompson | S37: Q4 | T37: Yes
A38: SL00036 | B38: Mar | C38: 2022 | D38: Drawing Tablet | E38: Input | F38: Sudurpashchim | G38: Corporate | H38: 498 | I38: 9999 | J38: =H38*I38 -> 4979502 | K38: =J38*0.64 -> 3186881.3 | L38: =J38-K38 -> 1792620.7 | M38: =IF(J38=0,0,L38/J38) -> 0.36 | N38: 0.09 | O38: =J38*(1-N38) -> 4531346.8 | P38: 2 | Q38: =IF(H38=0,0,P38/H38) -> 0.0040160643 | R38: Jerry Anderson | S38: Q1 | T38: Yes
A39: SL00037 | B39: Jul | C39: 2023 | D39: LED Desk Lamp | E39: Accessories | F39: Lumbini | G39: Retail Store | H39: 68 | I39: 8999 | J39: =H39*I39 -> 611932 | K39: =J39*0.47 -> 287608.04 | L39: =J39-K39 -> 324323.96 | M39: =IF(J39=0,0,L39/J39) -> 0.53 | N39: 0.09 | O39: =J39*(1-N39) -> 556858.12 | P39: 0 | Q39: =IF(H39=0,0,P39/H39) -> 0 | R39: Kristie Gonzalez | S39: Q3 | T39: No
A40: SL00038 | B40: May | C40: 2022 | D40: SSD 1TB | E40: Storage | F40: Madhesh | G40: Corporate | H40: 397 | I40: 3999 | J40: =H40*I40 -> 1587603 | K40: =J40*0.48 -> 762049.44 | L40: =J40-K40 -> 825553.56 | M40: =IF(J40=0,0,L40/J40) -> 0.52 | N40: 0.02 | O40: =J40*(1-N40) -> 1555850.9 | P40: 17 | Q40: =IF(H40=0,0,P40/H40) -> 0.042821159 | R40: Michael Perez DDS | S40: Q2 | T40: Yes
...

Sheet Student Records
A1: 🎓 Student Academic Records — 2024
A2: Student ID | B2: Full Name | C2: Program | D2: Semester | E2: Academic Year | F2: Subject 1 | G2: Sub1 Score | H2: Subject 2 | I2: Sub2 Score | J2: Subject 3 | K2: Sub3 Score | L2: Total Marks | M2: Percentage | N2: Grade | O2: GPA | P2: Attendance % | Q2: Assignment Score | R2: Practical Score | S2: Pass/Fail | T2: Scholarship?
A3: STU00001 | B3: Peter Allen | C3: BSc CSIT | D3: 1 | E3: 2022-23 | F3: English | G3: 57 | H3: Networking | I3: 92 | J3: Statistics | K3: 70 | L3: =G3+I3+K3 -> 219 | M3: =L3/300*100 -> 73 | N3: =IF(M3>=90,"A+",IF(M3>=80,"A",IF(M3>=70,"B+",IF(M3>=60,"B",IF(M3>=50,"C","F"))))) -> B+ | O3: =IF(M3>=90,4,IF(M3>=80,3.7,IF(M3>=70,3.3,IF(M3>=60,3,IF(M3>=50,2,0))))) -> 3.3 | P3: 0.573 | Q3: 40.5 | R3: 77.8 | S3: =IF(M3>=40,"Pass","Fail") -> Pass | T3: =IF(M3>=80,"Yes","No") -> No
A4: STU00002 | B4: Raymond Mccarthy | C4: BHM | D4: 7 | E4: 2022-23 | F4: Web Technology | G4: 24 | H4: Statistics | I4: 82 | J4: AI & ML | K4: 71 | L4: =G4+I4+K4 -> 177 | M4: =L4/300*100 -> 59 | N4: =IF(M4>=90,"A+",IF(M4>=80,"A",IF(M4>=70,"B+",IF(M4>=60,"B",IF(M4>=50,"C","F"))))) -> C | O4: =IF(M4>=90,4,IF(M4>=80,3.7,IF(M4>=70,3.3,IF(M4>=60,3,IF(M4>=50,2,0))))) -> 2 | P4: 0.769 | Q4: 75.5 | R4: 76.7 | S4: =IF(M4>=40,"Pass","Fail") -> Pass | T4: =IF(M4>=80,"Yes","No") -> No
A5: STU00003 | B5: Ryan Stewart | C5: BHM | D5: 8 | E5: 2021-22 | F5: Mathematics | G5: 74 | H5: Statistics | I5: 93 | J5: English | K5: 60 | L5: =G5+I5+K5 -> 227 | M5: =L5/300*100 -> 75.666667 | N5: =IF(M5>=90,"A+",IF(M5>=80,"A",IF(M5>=70,"B+",IF(M5>=60,"B",IF(M5>=50,"C","F"))))) -> B+ | O5: =IF(M5>=90,4,IF(M5>=80,3.7,IF(M5>=70,3.3,IF(M5>=60,3,IF(M5>=50,2,0))))) -> 3.3 | P5: 0.799 | Q5: 56.1 | R5: 78.9 | S5: =IF(M5>=40,"Pass","Fail") -> Pass | T5: =IF(M5>=80,"Yes","No") -> No
A6: STU00004 | B6: Larry Lewis | C6: BSc CSIT | D6: 2 | E6: 2022-23 | F6: English | G6: 75 | H6: Software Engineering | I6: 22 | J6: Web Technology | K6: 40 | L6: =G6+I6+K6 -> 137 | M6: =L6/300*100 -> 45.666667 | N6: =IF(M6>=90,"A+",IF(M6>=80,"A",IF(M6>=70,"B+",IF(M6>=60,"B",IF(M6>=50,"C","F"))))) -> F | O6: =IF(M6>=90,4,IF(M6>=80,3.7,IF(M6>=70,3.3,IF(M6>=60,3,IF(M6>=50,2,0))))) -> 0 | P6: 0.68 | Q6: 51.5 | R6: 60.6 | S6: =IF(M6>=40,"Pass","Fail") -> Pass | T6: =IF(M6>=80,"Yes","No") -> No
A7: STU00005 | B7: Mark Ramirez | C7: BIT | D7: 4 | E7: 2023-24 | F7: Software Engineering | G7: 57 | H7: Web Technology | I7: 69 | J7: Database | K7: 73 | L7: =G7+I7+K7 -> 199 | M7: =L7/300*100 -> 66.333333 | N7: =IF(M7>=90,"A+",IF(M7>=80,"A",IF(M7>=70,"B+",IF(M7>=60,"B",IF(M7>=50,"C","F"))))) -> B | O7: =IF(M7>=90,4,IF(M7>=80,3.7,IF(M7>=70,3.3,IF(M7>=60,3,IF(M7>=50,2,0))))) -> 3 | P7: 0.925 | Q7: 80.4 | R7: 84.1 | S7: =IF(M7>=40,"Pass","Fail") -> Pass | T7: =IF(M7>=80,"Yes","No") -> No
A8: STU00006 | B8: Jeffrey Alexander | C8: B.Eng | D8: 8 | E8: 2021-22 | F8: English | G8: 31 | H8: Networking | I8: 81 | J8: AI & ML | K8: 36 | L8: =G8+I8+K8 -> 148 | M8: =L8/300*100 -> 49.333333 | N8: =IF(M8>=90,"A+",IF(M8>=80,"A",IF(M8>=70,"B+",IF(M8>=60,"B",IF(M8>=50,"C","F"))))) -> F | O8: =IF(M8>=90,4,IF(M8>=80,3.7,IF(M8>=70,3.3,IF(M8>=60,3,IF(M8>=50,2,0))))) -> 0 | P8: 0.628 | Q8: 49.4 | R8: 69.5 | S8: =IF(M8>=40,"Pass","Fail") -> Pass | T8: =IF(M8>=80,"Yes","No") -> No
A9: STU00007 | B9: Danielle Martinez | C9: B.Eng | D9: 7 | E9: 2022-23 | F9: AI & ML | G9: 91 | H9: Networking | I9: 26 | J9: Statistics | K9: 22 | L9: =G9+I9+K9 -> 139 | M9: =L9/300*100 -> 46.333333 | N9: =IF(M9>=90,"A+",IF(M9>=80,"A",IF(M9>=70,"B+",IF(M9>=60,"B",IF(M9>=50,"C","F"))))) -> F | O9: =IF(M9>=90,4,IF(M9>=80,3.7,IF(M9>=70,3.3,IF(M9>=60,3,IF(M9>=50,2,0))))) -> 0 | P9: 0.711 | Q9: 55.6 | R9: 80.6 | S9: =IF(M9>=40,"Pass","Fail") -> Pass | T9: =IF(M9>=80,"Yes","No") -> No
A10: STU00008 | B10: Marissa Thompson | C10: BIT | D10: 1 | E10: 2021-22 | F10: Software Engineering | G10: 99 | H10: Operating System | I10: 49 | J10: Programming | K10: 35 | L10: =G10+I10+K10 -> 183 | M10: =L10/300*100 -> 61 | N10: =IF(M10>=90,"A+",IF(M10>=80,"A",IF(M10>=70,"B+",IF(M10>=60,"B",IF(M10>=50,"C","F"))))) -> B | O10: =IF(M10>=90,4,IF(M10>=80,3.7,IF(M10>=70,3.3,IF(M10>=60,3,IF(M10>=50,2,0))))) -> 3 | P10: 0.803 | Q10: 69.2 | R10: 99.6 | S10: =IF(M10>=40,"Pass","Fail") -> Pass | T10: =IF(M10>=80,"Yes","No") -> No
A11: STU00009 | B11: Savannah Townsend | C11: B.Eng | D11: 6 | E11: 2021-22 | F11: Statistics | G11: 85 | H11: AI & ML | I11: 97 | J11: Database | K11: 33 | L11: =G11+I11+K11 -> 215 | M11: =L11/300*100 -> 71.666667 | N11: =IF(M11>=90,"A+",IF(M11>=80,"A",IF(M11>=70,"B+",IF(M11>=60,"B",IF(M11>=50,"C","F"))))) -> B+ | O11: =IF(M11>=90,4,IF(M11>=80,3.7,IF(M11>=70,3.3,IF(M11>=60,3,IF(M11>=50,2,0))))) -> 3.3 | P11: 0.868 | Q11: 95.6 | R11: 66.3 | S11: =IF(M11>=40,"Pass","Fail") -> Pass | T11: =IF(M11>=80,"Yes","No") -> No
A12: STU00010 | B12: Jeff Jensen | C12: BSc CSIT | D12: 2 | E12: 2021-22 | F12: English | G12: 84 | H12: Programming | I12: 33 | J12: Mathematics | K12: 41 | L12: =G12+I12+K12 -> 158 | M12: =L12/300*100 -> 52.666667 | N12: =IF(M12>=90,"A+",IF(M12>=80,"A",IF(M12>=70,"B+",IF(M12>=60,"B",IF(M12>=50,"C","F"))))) -> C | O12: =IF(M12>=90,4,IF(M12>=80,3.7,IF(M12>=70,3.3,IF(M12>=60,3,IF(M12>=50,2,0))))) -> 2 | P12: 0.833 | Q12: 92.3 | R12: 94.7 | S12: =IF(M12>=40,"Pass","Fail") -> Pass | T12: =IF(M12>=80,"Yes","No") -> No
A13: STU00011 | B13: Tammie Lee | C13: BIT | D13: 5 | E13: 2023-24 | F13: Web Technology | G13: 32 | H13: Statistics | I13: 39 | J13: English | K13: 66 | L13: =G13+I13+K13 -> 137 | M13: =L13/300*100 -> 45.666667 | N13: =IF(M13>=90,"A+",IF(M13>=80,"A",IF(M13>=70,"B+",IF(M13>=60,"B",IF(M13>=50,"C","F"))))) -> F | O13: =IF(M13>=90,4,IF(M13>=80,3.7,IF(M13>=70,3.3,IF(M13>=60,3,IF(M13>=50,2,0))))) -> 0 | P13: 0.701 | Q13: 48.3 | R13: 90.9 | S13: =IF(M13>=40,"Pass","Fail") -> Pass | T13: =IF(M13>=80,"Yes","No") -> No
A14: STU00012 | B14: Timothy Cowan | C14: BSc CSIT | D14: 7 | E14: 2021-22 | F14: Networking | G14: 56 | H14: Web Technology | I14: 84 | J14: Software Engineering | K14: 41 | L14: =G14+I14+K14 -> 181 | M14: =L14/300*100 -> 60.333333 | N14: =IF(M14>=90,"A+",IF(M14>=80,"A",IF(M14>=70,"B+",IF(M14>=60,"B",IF(M14>=50,"C","F"))))) -> B | O14: =IF(M14>=90,4,IF(M14>=80,3.7,IF(M14>=70,3.3,IF(M14>=60,3,IF(M14>=50,2,0))))) -> 3 | P14: 0.588 | Q14: 62.3 | R14: 85.3 | S14: =IF(M14>=40,"Pass","Fail") -> Pass | T14: =IF(M14>=80,"Yes","No") -> No
... A402: STU00400 | B402: Kimberly Bishop | C402: BHM | D402: 5 | E402: 2021-22 | F402: Software Engineering | G402: 31 | H402: Statistics | I402: 85 | J402: AI & ML | K402: 46 | L402: =G402+I402+K402 -> 162 | M402: =L402/300*100 -> 54 | N402: =IF(M402>=90,"A+",IF(M402>=80,"A",IF(M402>=70,"B+",IF(M402>=60,"B",IF(M402>=50,"C","F"))))) -> C | O402: =IF(M402>=90,4,IF(M402>=80,3.7,IF(M402>=70,3.3,IF(M402>=60,3,IF(M402>=50,2,0))))) -> 2 | P402: 0.666 | Q402: 68.1 | R402: 41.9 | S402: =IF(M402>=40,"Pass","Fail") -> Pass | T402: =IF(M402>=80,"Yes","No") -> No
A403: AVERAGES | G403: =AVERAGE(G3:G402) -> 58.205 | I403: =AVERAGE(I3:I402) -> 60.94 | K403: =AVERAGE(K3:K402) -> 59.7 | L403: =AVERAGE(L3:L402) -> 178.845 | M403: =AVERAGE(M3:M402) -> 59.615 | O403: =AVERAGE(O3:O402) -> 2.143 | P403: =AVERAGE(P3:P402) -> 0.7638225

Sheet Inventory
A1: 📦 Inventory & Stock Management
A2: SKU | B2: Product Name | C2: Category | D2: Supplier | E2: Unit Cost (NPR) | F2: Selling Price (NPR) | G2: Markup % | H2: Stock Qty | I2: Reorder Level | J2: Stock Value (NPR) | K2: Last Restocked | L2: Avg Monthly Sales | M2: Months of Stock | N2: Status | O2: Location | P2: Condition | Q2: Warranty (Months) | R2: Weight (kg) | S2: In Transit | T2: Total Assets (NPR)
A3: SKU0001 | B3: Laptop Pro 15 | C3: Electronics | D3: Digital Hub | E3: 86700 | F3: 147800 | G3: =(F3-E3)/E3 -> 0.70472895 | H3: 243 | I3: 13 | J3: =H3*E3 -> 21068100 | K3: 45348 | L3: 37.9 | M3: =IF(L3=0,"N/A",TEXT(H3/L3,"0.0")) -> 6.4 | N3: =IF(H3=0,"Out of Stock",IF(H3<I3,"Low Stock","In Stock")) -> In Stock | O3: Overflow | P3: New | Q3: 24 | R3: 5.65 | S3: 10 | T3: =(H3+S3)*E3 -> 21935100
A4: SKU0002 | B4: Laptop Air 13 | C4: Networking | D4: Prime Wholesale | E4: 14200 | F4: 24200 | G4: =(F4-E4)/E4 -> 0.70422535 | H4: 445 | I4: 5 | J4: =H4*E4 -> 6319000 | K4: 45613 | L4: 13.5 | M4: =IF(L4=0,"N/A",TEXT(H4/L4,"0.0")) -> 33.0 | N4: =IF(H4=0,"Out of Stock",IF(H4<I4,"Low Stock","In Stock")) -> In Stock | O4: Warehouse B | P4: New | Q4: 6 | R4: 5.09 | S4: 15 | T4: =(H4+S4)*E4 -> 6532000
A5: SKU0003 | B5: Gaming PC Tower | C5: Networking | D5: Himalayan Distributors | E5: 61600 | F5: 100900 | G5: =(F5-E5)/E5 -> 0.63798701 | H5: 385 | I5: 6 | J5: =H5*E5 -> 23716000 | K5: 45567 | L5: 35.7 | M5: =IF(L5=0,"N/A",TEXT(H5/L5,"0.0")) -> 10.8 | N5: =IF(H5=0,"Out of Stock",IF(H5<I5,"Low Stock","In Stock")) -> In Stock | O5: Cold Storage | P5: Refurbished | Q5: 36 | R5: 6.9 | S5: 19 | T5: =(H5+S5)*E5 -> 24886400
A6: SKU0004 | B6: Mini PC | C6: Storage | D6: Alpha Traders | E6: 32400 | F6: 45400 | G6: =(F6-E6)/E6 -> 0.40123457 | H6: 191 | I6: 43 | J6: =H6*E6 -> 6188400 | K6: 45554 | L6: 27.7 | M6: =IF(L6=0,"N/A",TEXT(H6/L6,"0.0")) -> 6.9 | N6: =IF(H6=0,"Out of Stock",IF(H6<I6,"Low Stock","In Stock")) -> In Stock | O6: Warehouse B | P6: Damaged | Q6: 6 | R6: 6.08 | S6: 21 | T6: =(H6+S6)*E6 -> 6868800
A7: SKU0005 | B7: Workstation Elite | C7: Electronics | D7: Star Imports | E7: 56300 | F7: 102400 | G7: =(F7-E7)/E7 -> 0.81882771 | H7: 488 | I7: 41 | J7: =H7*E7 -> 27474400 | K7: 45611 | L7: 32.7 | M7: =IF(L7=0,"N/A",TEXT(H7/L7,"0.0")) -> 14.9 | N7: =IF(H7=0,"Out of Stock",IF(H7<I7,"Low Stock","In Stock")) -> In Stock | O7: Showroom | P7: Damaged | Q7: 12 | R7: 2.54 | S7: 0 | T7: =(H7+S7)*E7 -> 27474400
A8: SKU0006 | B8: Wireless Mouse Pro | C8: Audio | D8: Digital Hub | E8: 26500 | F8: 52000 | G8: =(F8-E8)/E8 -> 0.96226415 | H8: 290 | I8: 13 | J8: =H8*E8 -> 7685000 | K8: 45638 | L8: 11.3 | M8: =IF(L8=0,"N/A",TEXT(H8/L8,"0.0")) -> 25.7 | N8: =IF(H8=0,"Out of Stock",IF(H8<I8,"Low Stock","In Stock")) -> In Stock | O8: Warehouse A | P8: New | Q8: 6 | R8: 11.85 | S8: 10 | T8: =(H8+S8)*E8 -> 7950000
A9: SKU0007 | B9: Mechanical KB RGB | C9: Computing | D9: Alpha Traders | E9: 19000 | F9: 35000 | G9: =(F9-E9)/E9 -> 0.84210526 | H9: 234 | I9: 30 | J9: =H9*E9 -> 4446000 | K9: 45306 | L9: 14.1 | M9: =IF(L9=0,"N/A",TEXT(H9/L9,"0.0")) -> 16.6 | N9: =IF(H9=0,"Out of Stock",IF(H9<I9,"Low Stock","In Stock")) -> In Stock | O9: Warehouse B | P9: New | Q9: 12 | R9: 9.91 | S9: 0 | T9: =(H9+S9)*E9 -> 4446000
A10: SKU0008 | B10: Trackpad Plus | C10: Networking | D10: TechNepal Pvt Ltd | E10: 24600 | F10: 34200 | G10: =(F10-E10)/E10 -> 0.3902439 | H10: 104 | I10: 32 | J10: =H10*E10 -> 2558400 | K10: 45597 | L10: 8.1 | M10: =IF(L10=0,"N/A",TEXT(H10/L10,"0.0")) -> 12.8 | N10: =IF(H10=0,"Out of Stock",IF(H10<I10,"Low Stock","In Stock")) -> In Stock | O10: Showroom | P10: New | Q10: 36 | R10: 2.4 | S10: 7 | T10: =(H10+S10)*E10 -> 2730600
A11: SKU0009 | B11: Numpad Slim | C11: Storage | D11: Himalayan Distributors | E11: 45600 | F11: 58400 | G11: =(F11-E11)/E11 -> 0.28070175 | H11: 281 | I11: 48 | J11: =H11*E11 -> 12813600 | K11: 45385 | L11: 32.1 | M11: =IF(L11=0,"N/A",TEXT(H11/L11,"0.0")) -> 8.8 | N11: =IF(H11=0,"Out of Stock",IF(H11<I11,"Low Stock","In Stock")) -> In Stock | O11: Cold Storage | P11: New | Q11: 24 | R11: 13.7 | S11: 6 | T11: =(H11+S11)*E11 -> 13087200
A12: SKU0010 | B12: Wrist Rest | C12: Computing | D12: TechNepal Pvt Ltd | E12: 51300 | F12: 66800 | G12: =(F12-E12)/E12 -> 0.30214425 | H12: 390 | I12: 13 | J12: =H12*E12 -> 20007000 | K12: 45520 | L12: 32.6 | M12: =IF(L12=0,"N/A",TEXT(H12/L12,"0.0")) -> 12.0 | N12: =IF(H12=0,"Out of Stock",IF(H12<I12,"Low Stock","In Stock")) -> In Stock | O12: Overflow | P12: Refurbished | Q12: 24 | R12: 13.48 | S12: 10 | T12: =(H12+S12)*E12 -> 20520000
A13: SKU0011 | B13: 24" FHD Monitor | C13: Display | D13: TechNepal Pvt Ltd | E13: 45900 | F13: 73000 | G13: =(F13-E13)/E13 -> 0.59041394 | H13: 379 | I13: 42 | J13: =H13*E13 -> 17396100 | K13: 45447 | L13: 3.1 | M13: =IF(L13=0,"N/A",TEXT(H13/L13,"0.0")) -> 122.3 | N13: =IF(H13=0,"Out of Stock",IF(H13<I13,"Low Stock","In Stock")) -> In Stock | O13: Showroom | P13: New | Q13: 12 | R13: 9.17 | S13: 28 | T13: =(H13+S13)*E13 -> 18681300
A14: SKU0012 | B14: 27" QHD Monitor | C14: Networking | D14: Digital Hub | E14: 108400 | F14: 130200 | G14: =(F14-E14)/E14 -> 0.20110701 | H14: 306 | I14: 30 | J14: =H14*E14 -> 33170400 | K14: 45353 | L14: 73.3 | M14: =IF(L14=0,"N/A",TEXT(H14/L14,"0.0")) -> 4.2 | N14: =IF(H14=0,"Out of Stock",IF(H14<I14,"Low Stock","In Stock")) -> In Stock | O14: Warehouse B | P14: New | Q14: 24 | R14: 3.53 | S14: 20 | T14: =(H14+S14)*E14 -> 35338400
... A252: SKU0250 | B252: Desk Organiser | C252: Electronics | D252: Prime Wholesale | E252: 74300 | F252: 117700 | G252: =(F252-E252)/E252 -> 0.58411844 | H252: 374 | I252: 49 | J252: =H252*E252 -> 27788200 | K252: 45574 | L252: 13.1 | M252: =IF(L252=0,"N/A",TEXT(H252/L252,"0.0")) -> 28.5 | N252: =IF(H252=0,"Out of Stock",IF(H252<I252,"Low Stock","In Stock")) -> In Stock | O252: Warehouse A | P252: New | Q252: 24 | R252: 6.02 | S252: 2 | T252: =(H252+S252)*E252 -> 27936800
A253: TOTALS | H253: =SUM(H3:H252) -> 63870 | J253: =SUM(J3:J252) -> 3606432600 | T253: =SUM(T3:T252) -> 3827058500
